<?xml version="1.0" encoding="utf-8"?>
<!-- This URDF was automatically created by SolidWorks to URDF Exporter! Originally created by Stephen Brawner (brawner@gmail.com) 
     Commit Version: 1.5.1-0-g916b5db  Build Version: 1.5.7152.31018
     For more information, please see http://wiki.ros.org/sw_urdf_exporter -->
<robot
  name="dof92">
  <link
    name="base_link">
    <inertial>
      <origin
        xyz="9.1669E-19 0.0006188 0.01308"
        rpy="0 0 0" />
      <mass
        value="0.38246" />
      <inertia
        ixx="0.00043672"
        ixy="-5.14E-21"
        ixz="6.9161E-21"
        iyy="0.00045103"
        iyz="7.29E-07"
        izz="0.00083789" />
    </inertial>
    <visual>
      <origin
        xyz="0 0 0"
        rpy="0 0 0" />
      <geometry>
        <mesh
          filename="package://dof92/meshes/base_link.STL" />
      </geometry>
      <material
        name="">
        <color
          rgba="1 1 1 1" />
      </material>
    </visual>
    <collision>
      <origin
        xyz="0 0 0"
        rpy="0 0 0" />
      <geometry>
        <mesh
          filename="package://dof92/meshes/base_link.STL" />
      </geometry>
    </collision>
  </link>
  <link
    name="Link1">
    <inertial>
      <origin
        xyz="4.2686E-10 -8.9895E-05 0.0063042"
        rpy="0 0 0" />
      <mass
        value="1.0794" />
      <inertia
        ixx="0.0020879"
        ixy="-1.4826E-10"
        ixz="3.8162E-10"
        iyy="0.0016041"
        iyz="-6.1066E-07"
        izz="0.0019142" />
    </inertial>
    <visual>
      <origin
        xyz="0 0 0"
        rpy="0 0 0" />
      <geometry>
        <mesh
          filename="package://dof92/meshes/Link1.STL" />
      </geometry>
      <material
        name="">
        <color
          rgba="1 1 1 1" />
      </material>
    </visual>
    <collision>
      <origin
        xyz="0 0 0"
        rpy="0 0 0" />
      <geometry>
        <mesh
          filename="package://dof92/meshes/Link1.STL" />
      </geometry>
    </collision>
  </link>
  <joint
    name="joint1"
    type="revolute">
    <origin
      xyz="0 0 0.09"
      rpy="1.5708 0 3.1416" />
    <parent
      link="base_link" />
    <child
      link="Link1" />
    <axis
      xyz="0 1 0" />
    <limit
      lower="-3.14"
      upper="3.14"
      effort="100"
      velocity="3" />
  </joint>
  <link
    name="Link2">
    <inertial>
      <origin
        xyz="0.20999 -6.7298E-12 0.11992"
        rpy="0 0 0" />
      <mass
        value="2.5593" />
      <inertia
        ixx="0.0045543"
        ixy="9.5236E-10"
        ixz="5.851E-07"
        iyy="0.097115"
        iyz="7.8875E-13"
        izz="0.096147" />
    </inertial>
    <visual>
      <origin
        xyz="0 0 0"
        rpy="0 0 0" />
      <geometry>
        <mesh
          filename="package://dof92/meshes/Link2.STL" />
      </geometry>
      <material
        name="">
        <color
          rgba="1 1 1 1" />
      </material>
    </visual>
    <collision>
      <origin
        xyz="0 0 0"
        rpy="0 0 0" />
      <geometry>
        <mesh
          filename="package://dof92/meshes/Link2.STL" />
      </geometry>
    </collision>
  </link>
  <joint
    name="joint2"
    type="revolute">
    <origin
      xyz="-0.42 0 0"
      rpy="0 0 0" />
    <parent
      link="Link1" />
    <child
      link="Link2" />
    <axis
      xyz="0 0 1" />
    <limit
      lower="-3.14"
      upper="3.14"
      effort="100"
      velocity="3" />
  </joint>
  <link
    name="Link3">
    <inertial>
      <origin
        xyz="0.14169 9.2965E-08 0.0025574"
        rpy="0 0 0" />
      <mass
        value="1.171" />
      <inertia
        ixx="0.0016099"
        ixy="-1.5523E-08"
        ixz="-0.00077623"
        iyy="0.030623"
        iyz="2.78E-08"
        izz="0.03039" />
    </inertial>
    <visual>
      <origin
        xyz="0 0 0"
        rpy="0 0 0" />
      <geometry>
        <mesh
          filename="package://dof92/meshes/Link3.STL" />
      </geometry>
      <material
        name="">
        <color
          rgba="1 1 1 1" />
      </material>
    </visual>
    <collision>
      <origin
        xyz="0 0 0"
        rpy="0 0 0" />
      <geometry>
        <mesh
          filename="package://dof92/meshes/Link3.STL" />
      </geometry>
    </collision>
  </link>
  <joint
    name="joint3"
    type="revolute">
    <origin
      xyz="-0.4 0 0"
      rpy="0 0 0" />
    <parent
      link="Link2" />
    <child
      link="Link3" />
    <axis
      xyz="0 0 1" />
    <limit
      lower="-3.14"
      upper="3.14"
      effort="100"
      velocity="3" />
  </joint>
  <link
    name="Link4">
    <inertial>
      <origin
        xyz="1.2298E-09 -0.0056137 0.00011006"
        rpy="0 0 0" />
      <mass
        value="0.58201" />
      <inertia
        ixx="0.0007618"
        ixy="1.4963E-11"
        ixz="4.4791E-11"
        iyy="0.00068944"
        iyz="-3.5959E-07"
        izz="0.00056434" />
    </inertial>
    <visual>
      <origin
        xyz="0 0 0"
        rpy="0 0 0" />
      <geometry>
        <mesh
          filename="package://dof92/meshes/Link4.STL" />
      </geometry>
      <material
        name="">
        <color
          rgba="1 1 1 1" />
      </material>
    </visual>
    <collision>
      <origin
        xyz="0 0 0"
        rpy="0 0 0" />
      <geometry>
        <mesh
          filename="package://dof92/meshes/Link4.STL" />
      </geometry>
    </collision>
  </link>
  <joint
    name="joint4"
    type="revolute">
    <origin
      xyz="0 0 0.1"
      rpy="1.5708 0 0" />
    <parent
      link="Link3" />
    <child
      link="Link4" />
    <axis
      xyz="0 -1 0" />
    <limit
      lower="-3.14"
      upper="3.14"
      effort="100"
      velocity="3" />
  </joint>
  <link
    name="Link5">
    <inertial>
      <origin
        xyz="1.7409E-07 0.0040239 -0.10572"
        rpy="0 0 0" />
      <mass
        value="0.81197" />
      <inertia
        ixx="0.024896"
        ixy="-2.8768E-09"
        ixz="-1.0498E-08"
        iyy="0.024963"
        iyz="-0.00034542"
        izz="0.0007983" />
    </inertial>
    <visual>
      <origin
        xyz="0 0 0"
        rpy="0 0 0" />
      <geometry>
        <mesh
          filename="package://dof92/meshes/Link5.STL" />
      </geometry>
      <material
        name="">
        <color
          rgba="1 1 1 1" />
      </material>
    </visual>
    <collision>
      <origin
        xyz="0 0 0"
        rpy="0 0 0" />
      <geometry>
        <mesh
          filename="package://dof92/meshes/Link5.STL" />
      </geometry>
    </collision>
  </link>
  <joint
    name="joint5"
    type="revolute">
    <origin
      xyz="0 0 0.1"
      rpy="-1.5708 0 0" />
    <parent
      link="Link4" />
    <child
      link="Link5" />
    <axis
      xyz="0 -1 0" />
    <limit
      lower="-3.14"
      upper="3.14"
      effort="100"
      velocity="3" />
  </joint>
  <link
    name="Link6">
    <inertial>
      <origin
        xyz="-2.2204E-16 4.3368E-17 -0.015"
        rpy="0 0 0" />
      <mass
        value="0.12931" />
      <inertia
        ixx="6.9588E-05"
        ixy="1.8267E-20"
        ixz="-2.397E-20"
        iyy="5.8731E-05"
        iyz="3.5387E-20"
        izz="0.00010892" />
    </inertial>
    <visual>
      <origin
        xyz="0 0 0"
        rpy="0 0 0" />
      <geometry>
        <mesh
          filename="package://dof92/meshes/Link6.STL" />
      </geometry>
      <material
        name="">
        <color
          rgba="1 1 1 1" />
      </material>
    </visual>
    <collision>
      <origin
        xyz="0 0 0"
        rpy="0 0 0" />
      <geometry>
        <mesh
          filename="package://dof92/meshes/Link6.STL" />
      </geometry>
    </collision>
  </link>
  <joint
    name="joint6p"
    type="prismatic">
    <origin
      xyz="0 0 -0.42"
      rpy="0 0 0" />
    <parent
      link="Link5" />
    <child
      link="Link6" />
    <axis
      xyz="0 0 1" />
    <limit
      lower="0"
      upper="0.5"
      effort="100"
      velocity="3" />
  </joint>
  <link
    name="Link7">
    <inertial>
      <origin
        xyz="3.1885E-09 -0.29766 2.9817E-08"
        rpy="0 0 0" />
      <mass
        value="0.18362" />
      <inertia
        ixx="0.0052429"
        ixy="-1.4282E-10"
        ixz="2.891E-13"
        iyy="9.233E-06"
        iyz="-1.3378E-09"
        izz="0.0052429" />
    </inertial>
    <visual>
      <origin
        xyz="0 0 0"
        rpy="0 0 0" />
      <geometry>
        <mesh
          filename="package://dof92/meshes/Link7.STL" />
      </geometry>
      <material
        name="">
        <color
          rgba="1 1 1 1" />
      </material>
    </visual>
    <collision>
      <origin
        xyz="0 0 0"
        rpy="0 0 0" />
      <geometry>
        <mesh
          filename="package://dof92/meshes/Link7.STL" />
      </geometry>
    </collision>
  </link>
  <joint
    name="joint7"
    type="revolute">
    <origin
      xyz="0 0 0.56"
      rpy="1.5708 0 0" />
    <parent
      link="Link6" />
    <child
      link="Link7" />
    <axis
      xyz="0 1 0" />
    <limit
      lower="-3.14"
      upper="3.14"
      effort="100"
      velocity="3" />
  </joint>
  <link
    name="Link8">
    <inertial>
      <origin
        xyz="-0.043248 -4.6718E-09 3.9744E-08"
        rpy="0 0 0" />
      <mass
        value="0.023875" />
      <inertia
        ixx="1.1971E-06"
        ixy="4.4295E-12"
        ixz="-3.8291E-11"
        iyy="1.4588E-05"
        iyz="8.1423E-14"
        izz="1.4442E-05" />
    </inertial>
    <visual>
      <origin
        xyz="0 0 0"
        rpy="0 0 0" />
      <geometry>
        <mesh
          filename="package://dof92/meshes/Link8.STL" />
      </geometry>
      <material
        name="">
        <color
          rgba="1 1 1 1" />
      </material>
    </visual>
    <collision>
      <origin
        xyz="0 0 0"
        rpy="0 0 0" />
      <geometry>
        <mesh
          filename="package://dof92/meshes/Link8.STL" />
      </geometry>
    </collision>
  </link>
  <joint
    name="joint8"
    type="revolute">
    <origin
      xyz="0.08 0 0"
      rpy="-1.5708 0 0" />
    <parent
      link="Link7" />
    <child
      link="Link8" />
    <axis
      xyz="0 1 0" />
    <limit
      lower="-3.14"
      upper="3.14"
      effort="100"
      velocity="3" />
  </joint>
  <link
    name="Link9">
    <inertial>
      <origin
        xyz="-0.062716 3.9899E-17 -5.5511E-17"
        rpy="0 0 0" />
      <mass
        value="0.030846" />
      <inertia
        ixx="1.4516E-06"
        ixy="2.511E-20"
        ixz="-1.8222E-19"
        iyy="2.7003E-05"
        iyz="-2.5042E-23"
        izz="2.7063E-05" />
    </inertial>
    <visual>
      <origin
        xyz="0 0 0"
        rpy="0 0 0" />
      <geometry>
        <mesh
          filename="package://dof92/meshes/Link9.STL" />
      </geometry>
      <material
        name="">
        <color
          rgba="1 1 1 1" />
      </material>
    </visual>
    <collision>
      <origin
        xyz="0 0 0"
        rpy="0 0 0" />
      <geometry>
        <mesh
          filename="package://dof92/meshes/Link9.STL" />
      </geometry>
    </collision>
  </link>
  <joint
    name="joint9"
    type="revolute">
    <origin
      xyz="0.11 0 0"
      rpy="0 0 0" />
    <parent
      link="Link8" />
    <child
      link="Link9" />
    <axis
      xyz="0 0 1" />
    <limit
      lower="-3.14"
      upper="3.14"
      effort="100"
      velocity="3" />
  </joint>
</robot>