<?xml version="1.0" encoding="utf-8"?>
<!-- This URDF was automatically created by SolidWorks to URDF Exporter! Originally created by Stephen Brawner (brawner@gmail.com) 
     Commit Version: 1.5.1-0-g916b5db  Build Version: 1.5.7152.31018
     For more information, please see http://wiki.ros.org/sw_urdf_exporter -->
<robot
  name="dofnine2">
  <link
    name="base_link">
    <inertial>
      <origin
        xyz="9.1669E-19 0.0006188 0.01308"
        rpy="0 0 0" />
      <mass
        value="0.38246" />
      <inertia
        ixx="0.00043672"
        ixy="-5.14E-21"
        ixz="6.9161E-21"
        iyy="0.00045103"
        iyz="7.29E-07"
        izz="0.00083789" />
    </inertial>
    <visual>
      <origin
        xyz="0 0 0"
        rpy="0 0 0" />
      <geometry>
        <mesh
          filename="package://dofnine2/meshes/base_link.STL" />
      </geometry>
      <material
        name="">
        <color
          rgba="1 1 1 1" />
      </material>
    </visual>
    <collision>
      <origin
        xyz="0 0 0"
        rpy="0 0 0" />
      <geometry>
        <mesh
          filename="package://dofnine2/meshes/base_link.STL" />
      </geometry>
    </collision>
  </link>
  <link
    name="Link1">
    <inertial>
      <origin
        xyz="4.2686E-10 -8.9895E-05 0.0063042"
        rpy="0 0 0" />
      <mass
        value="1.0794" />
      <inertia
        ixx="0.0020879"
        ixy="-1.4826E-10"
        ixz="3.8162E-10"
        iyy="0.0016041"
        iyz="-6.1066E-07"
        izz="0.0019142" />
    </inertial>
    <visual>
      <origin
        xyz="0 0 0"
        rpy="0 0 0" />
      <geometry>
        <mesh
          filename="package://dofnine2/meshes/Link1.STL" />
      </geometry>
      <material
        name="">
        <color
          rgba="1 1 1 1" />
      </material>
    </visual>
    <collision>
      <origin
        xyz="0 0 0"
        rpy="0 0 0" />
      <geometry>
        <mesh
          filename="package://dofnine2/meshes/Link1.STL" />
      </geometry>
    </collision>
  </link>
  <joint
    name="joint1"
    type="revolute">
    <origin
      xyz="0 0 0.09"
      rpy="1.5708 0 3.1416" />
    <parent
      link="base_link" />
    <child
      link="Link1" />
    <axis
      xyz="0 1 0" />
    <limit
      lower="-3.14"
      upper="3.14"
      effort="100"
      velocity="3" />
  </joint>
  <link
    name="Link2">
    <inertial>
      <origin
        xyz="0.20999 -6.7298E-12 0.11992"
        rpy="0 0 0" />
      <mass
        value="2.5593" />
      <inertia
        ixx="0.0045543"
        ixy="9.5236E-10"
        ixz="5.851E-07"
        iyy="0.097115"
        iyz="7.8875E-13"
        izz="0.096147" />
    </inertial>
    <visual>
      <origin
        xyz="0 0 0"
        rpy="0 0 0" />
      <geometry>
        <mesh
          filename="package://dofnine2/meshes/Link2.STL" />
      </geometry>
      <material
        name="">
        <color
          rgba="1 1 1 1" />
      </material>
    </visual>
    <collision>
      <origin
        xyz="0 0 0"
        rpy="0 0 0" />
      <geometry>
        <mesh
          filename="package://dofnine2/meshes/Link2.STL" />
      </geometry>
    </collision>
  </link>
  <joint
    name="joint2"
    type="revolute">
    <origin
      xyz="-0.42 0 0"
      rpy="0 0 0" />
    <parent
      link="Link1" />
    <child
      link="Link2" />
    <axis
      xyz="0 0 1" />
    <limit
      lower="-3.14"
      upper="3.14"
      effort="100"
      velocity="3" />
  </joint>
  <link
    name="Link3">
    <inertial>
      <origin
        xyz="0.1417 9.2942E-08 0.002554"
        rpy="0 0 0" />
      <mass
        value="1.1711" />
      <inertia
        ixx="0.0016101"
        ixy="-1.5519E-08"
        ixz="-0.00077549"
        iyy="0.030627"
        iyz="2.7799E-08"
        izz="0.030394" />
    </inertial>
    <visual>
      <origin
        xyz="0 0 0"
        rpy="0 0 0" />
      <geometry>
        <mesh
          filename="package://dofnine2/meshes/Link3.STL" />
      </geometry>
      <material
        name="">
        <color
          rgba="1 1 1 1" />
      </material>
    </visual>
    <collision>
      <origin
        xyz="0 0 0"
        rpy="0 0 0" />
      <geometry>
        <mesh
          filename="package://dofnine2/meshes/Link3.STL" />
      </geometry>
    </collision>
  </link>
  <joint
    name="joint3"
    type="revolute">
    <origin
      xyz="-0.4 0 0"
      rpy="0 0 0" />
    <parent
      link="Link2" />
    <child
      link="Link3" />
    <axis
      xyz="0 0 1" />
    <limit
      lower="-3.14"
      upper="3.14"
      effort="100"
      velocity="3" />
  </joint>
  <link
    name="Link4">
    <inertial>
      <origin
        xyz="1.2298E-09 -0.0056137 0.00011006"
        rpy="0 0 0" />
      <mass
        value="0.58201" />
      <inertia
        ixx="0.0007618"
        ixy="1.4963E-11"
        ixz="4.4791E-11"
        iyy="0.00068944"
        iyz="-3.5959E-07"
        izz="0.00056434" />
    </inertial>
    <visual>
      <origin
        xyz="0 0 0"
        rpy="0 0 0" />
      <geometry>
        <mesh
          filename="package://dofnine2/meshes/Link4.STL" />
      </geometry>
      <material
        name="">
        <color
          rgba="1 1 1 1" />
      </material>
    </visual>
    <collision>
      <origin
        xyz="0 0 0"
        rpy="0 0 0" />
      <geometry>
        <mesh
          filename="package://dofnine2/meshes/Link4.STL" />
      </geometry>
    </collision>
  </link>
  <joint
    name="joint4"
    type="revolute">
    <origin
      xyz="0 0 0.1"
      rpy="1.5708 0 0" />
    <parent
      link="Link3" />
    <child
      link="Link4" />
    <axis
      xyz="0 -1 0" />
    <limit
      lower="-3.14"
      upper="3.14"
      effort="100"
      velocity="3" />
  </joint>
  <link
    name="Link5">
    <inertial>
      <origin
        xyz="-1.1025E-09 0.0060608 -0.00087677"
        rpy="0 0 0" />
      <mass
        value="0.53907" />
      <inertia
        ixx="0.00070005"
        ixy="2.8082E-11"
        ixz="-3.7536E-11"
        iyy="0.00062916"
        iyz="-2.8643E-06"
        izz="0.00054563" />
    </inertial>
    <visual>
      <origin
        xyz="0 0 0"
        rpy="0 0 0" />
      <geometry>
        <mesh
          filename="package://dofnine2/meshes/Link5.STL" />
      </geometry>
      <material
        name="">
        <color
          rgba="1 1 1 1" />
      </material>
    </visual>
    <collision>
      <origin
        xyz="0 0 0"
        rpy="0 0 0" />
      <geometry>
        <mesh
          filename="package://dofnine2/meshes/Link5.STL" />
      </geometry>
    </collision>
  </link>
  <joint
    name="joint5"
    type="revolute">
    <origin
      xyz="0 0 0.1"
      rpy="-1.5708 0 0" />
    <parent
      link="Link4" />
    <child
      link="Link5" />
    <axis
      xyz="0 -1 0" />
    <limit
      lower="-3.14"
      upper="3.14"
      effort="100"
      velocity="3" />
  </joint>
  <link
    name="Link6">
    <inertial>
      <origin
        xyz="-3.3307E-16 -5.6032E-16 -0.025"
        rpy="0 0 0" />
      <mass
        value="0.0032987" />
      <inertia
        ixx="8.6948E-07"
        ixy="-2.4815E-23"
        ixz="5.1433E-22"
        iyy="8.6948E-07"
        iyz="6.9358E-24"
        izz="3.645E-07" />
    </inertial>
    <visual>
      <origin
        xyz="0 0 0"
        rpy="0 0 0" />
      <geometry>
        <mesh
          filename="package://dofnine2/meshes/Link6.STL" />
      </geometry>
      <material
        name="">
        <color
          rgba="1 1 1 1" />
      </material>
    </visual>
    <collision>
      <origin
        xyz="0 0 0"
        rpy="0 0 0" />
      <geometry>
        <mesh
          filename="package://dofnine2/meshes/Link6.STL" />
      </geometry>
    </collision>
  </link>
  <joint
    name="joint6"
    type="revolute">
    <origin
      xyz="0 0 0.1"
      rpy="0 0 0" />
    <parent
      link="Link5" />
    <child
      link="Link6" />
    <axis
      xyz="0 0 1" />
    <limit
      lower="-3.14"
      upper="3.14"
      effort="100"
      velocity="3" />
  </joint>
  <link
    name="Link7">
    <inertial>
      <origin
        xyz="3.1885E-09 -0.29766 2.9817E-08"
        rpy="0 0 0" />
      <mass
        value="0.18362" />
      <inertia
        ixx="0.0052429"
        ixy="-1.4282E-10"
        ixz="2.891E-13"
        iyy="9.233E-06"
        iyz="-1.3378E-09"
        izz="0.0052429" />
    </inertial>
    <visual>
      <origin
        xyz="0 0 0"
        rpy="0 0 0" />
      <geometry>
        <mesh
          filename="package://dofnine2/meshes/Link7.STL" />
      </geometry>
      <material
        name="">
        <color
          rgba="1 1 1 1" />
      </material>
    </visual>
    <collision>
      <origin
        xyz="0 0 0"
        rpy="0 0 0" />
      <geometry>
        <mesh
          filename="package://dofnine2/meshes/Link7.STL" />
      </geometry>
    </collision>
  </link>
  <joint
    name="joint7"
    type="prismatic">
    <origin
      xyz="0 0 0"
      rpy="1.5708 0 0" />
    <parent
      link="Link6" />
    <child
      link="Link7" />
    <axis
      xyz="0 1 0" />
    <limit
      lower="0.01"
      upper="0.5"
      effort="100"
      velocity="3" />
  </joint>
  <link
    name="Link8">
    <inertial>
      <origin
        xyz="-0.043248 -4.6718E-09 3.9744E-08"
        rpy="0 0 0" />
      <mass
        value="0.023875" />
      <inertia
        ixx="1.1971E-06"
        ixy="4.4295E-12"
        ixz="-3.8291E-11"
        iyy="1.4588E-05"
        iyz="8.1423E-14"
        izz="1.4442E-05" />
    </inertial>
    <visual>
      <origin
        xyz="0 0 0"
        rpy="0 0 0" />
      <geometry>
        <mesh
          filename="package://dofnine2/meshes/Link8.STL" />
      </geometry>
      <material
        name="">
        <color
          rgba="1 1 1 1" />
      </material>
    </visual>
    <collision>
      <origin
        xyz="0 0 0"
        rpy="0 0 0" />
      <geometry>
        <mesh
          filename="package://dofnine2/meshes/Link8.STL" />
      </geometry>
    </collision>
  </link>
  <joint
    name="joint8"
    type="revolute">
    <origin
      xyz="0.08 0 0"
      rpy="-1.5708 0 0" />
    <parent
      link="Link7" />
    <child
      link="Link8" />
    <axis
      xyz="0 1 0" />
    <limit
      lower="-3.14"
      upper="3.14"
      effort="100"
      velocity="3" />
  </joint>
  <link
    name="Link9">
    <inertial>
      <origin
        xyz="-0.059037 3.9899E-17 -5.5511E-17"
        rpy="0 0 0" />
      <mass
        value="0.033078" />
      <inertia
        ixx="1.6325E-06"
        ixy="1.2125E-21"
        ixz="-1.9821E-19"
        iyy="3.3309E-05"
        iyz="-2.9569E-21"
        izz="3.3424E-05" />
    </inertial>
    <visual>
      <origin
        xyz="0 0 0"
        rpy="0 0 0" />
      <geometry>
        <mesh
          filename="package://dofnine2/meshes/Link9.STL" />
      </geometry>
      <material
        name="">
        <color
          rgba="1 1 1 1" />
      </material>
    </visual>
    <collision>
      <origin
        xyz="0 0 0"
        rpy="0 0 0" />
      <geometry>
        <mesh
          filename="package://dofnine2/meshes/Link9.STL" />
      </geometry>
    </collision>
  </link>
  <joint
    name="joint9"
    type="revolute">
    <origin
      xyz="0.11 0 0"
      rpy="0 0 0" />
    <parent
      link="Link8" />
    <child
      link="Link9" />
    <axis
      xyz="0 0 1" />
    <limit
      lower="-3.14"
      upper="3.14"
      effort="100"
      velocity="3" />
  </joint>
</robot>