<?xml version="1.0" encoding="utf-8"?>
<!-- This URDF was automatically created by SolidWorks to URDF Exporter! Originally created by Stephen Brawner (brawner@gmail.com) 
     Commit Version: 1.5.1-0-g916b5db  Build Version: 1.5.7152.31018
     For more information, please see http://wiki.ros.org/sw_urdf_exporter -->
<robot
  name="dofnine4">
  <link
    name="base_link">
    <inertial>
      <origin
        xyz="9.17014122667739E-19 0.000618795169331327 0.0130802854264847"
        rpy="0 0 0" />
      <mass
        value="0.382463662284906" />
      <inertia
        ixx="0.000436715101142595"
        ixy="-5.13379791175437E-21"
        ixz="6.91673726804431E-21"
        iyy="0.000451031799669551"
        iyz="7.29000884268053E-07"
        izz="0.000837893536635359" />
    </inertial>
    <visual>
      <origin
        xyz="0 0 0"
        rpy="0 0 0" />
      <geometry>
        <mesh
          filename="package://dofnine4/meshes/base_link.STL" />
      </geometry>
      <material
        name="">
        <color
          rgba="0.792156862745098 0.819607843137255 0.933333333333333 1" />
      </material>
    </visual>
    <collision>
      <origin
        xyz="0 0 0"
        rpy="0 0 0" />
      <geometry>
        <mesh
          filename="package://dofnine4/meshes/base_link.STL" />
      </geometry>
    </collision>
  </link>
  <link
    name="Link1">
    <inertial>
      <origin
        xyz="4.26856191622094E-10 -8.98950775120172E-05 0.00630420916246924"
        rpy="0 0 0" />
      <mass
        value="1.07941290222332" />
      <inertia
        ixx="0.00208785387880582"
        ixy="-1.4826084073053E-10"
        ixz="3.81615434706481E-10"
        iyy="0.00160413020613398"
        iyz="-6.10657722236426E-07"
        izz="0.00191423627434087" />
    </inertial>
    <visual>
      <origin
        xyz="0 0 0"
        rpy="0 0 0" />
      <geometry>
        <mesh
          filename="package://dofnine4/meshes/Link1.STL" />
      </geometry>
      <material
        name="">
        <color
          rgba="0.792156862745098 0.819607843137255 0.933333333333333 1" />
      </material>
    </visual>
    <collision>
      <origin
        xyz="0 0 0"
        rpy="0 0 0" />
      <geometry>
        <mesh
          filename="package://dofnine4/meshes/Link1.STL" />
      </geometry>
    </collision>
  </link>
  <joint
    name="joint1"
    type="revolute">
    <origin
      xyz="0 0 0.09"
      rpy="1.5708 0 3.1416" />
    <parent
      link="base_link" />
    <child
      link="Link1" />
    <axis
      xyz="0 1 0" />
    <limit
      lower="-3.14"
      upper="3.14"
      effort="100"
      velocity="3" />
  </joint>
  <link
    name="Link2">
    <inertial>
      <origin
        xyz="-0.210005372073954 -6.72978339721908E-12 0.119922540954011"
        rpy="0 0 0" />
      <mass
        value="2.55928066457366" />
      <inertia
        ixx="0.00455429949615839"
        ixy="9.5235852027459E-10"
        ixz="5.85104824094678E-07"
        iyy="0.0971147033093044"
        iyz="7.88752118663884E-13"
        izz="0.0961474311368105" />
    </inertial>
    <visual>
      <origin
        xyz="0 0 0"
        rpy="0 0 0" />
      <geometry>
        <mesh
          filename="package://dofnine4/meshes/Link2.STL" />
      </geometry>
      <material
        name="">
        <color
          rgba="0.792156862745098 0.819607843137255 0.933333333333333 1" />
      </material>
    </visual>
    <collision>
      <origin
        xyz="0 0 0"
        rpy="0 0 0" />
      <geometry>
        <mesh
          filename="package://dofnine4/meshes/Link2.STL" />
      </geometry>
    </collision>
  </link>
  <joint
    name="joint2"
    type="revolute">
    <origin
      xyz="0 0 0"
      rpy="0 0 0" />
    <parent
      link="Link1" />
    <child
      link="Link2" />
    <axis
      xyz="0 0 1" />
    <limit
      lower="-3.14"
      upper="3.14"
      effort="100"
      velocity="3" />
  </joint>
  <link
    name="Link3">
    <inertial>
      <origin
        xyz="-0.258297496495133 9.29424508328003E-08 0.00255403577713518"
        rpy="0 0 0" />
      <mass
        value="1.17113450129019" />
      <inertia
        ixx="0.00161010600022899"
        ixy="-1.55189359452696E-08"
        ixz="-0.000775488342638417"
        iyy="0.0306269407559279"
        iyz="2.77993622374225E-08"
        izz="0.030393600630592" />
    </inertial>
    <visual>
      <origin
        xyz="0 0 0"
        rpy="0 0 0" />
      <geometry>
        <mesh
          filename="package://dofnine4/meshes/Link3.STL" />
      </geometry>
      <material
        name="">
        <color
          rgba="1 1 1 1" />
      </material>
    </visual>
    <collision>
      <origin
        xyz="0 0 0"
        rpy="0 0 0" />
      <geometry>
        <mesh
          filename="package://dofnine4/meshes/Link3.STL" />
      </geometry>
    </collision>
  </link>
  <joint
    name="joint3"
    type="revolute">
    <origin
      xyz="-0.42 0 0"
      rpy="0 0 0" />
    <parent
      link="Link2" />
    <child
      link="Link3" />
    <axis
      xyz="0 0 1" />
    <limit
      lower="-3.14"
      upper="3.14"
      effort="100"
      velocity="3" />
  </joint>
  <link
    name="Link4">
    <inertial>
      <origin
        xyz="1.22980003958162E-09 -0.00561370801496067 0.000110059919152264"
        rpy="0 0 0" />
      <mass
        value="0.582005099414678" />
      <inertia
        ixx="0.000761796751548953"
        ixy="1.4963474595435E-11"
        ixz="4.47914161145852E-11"
        iyy="0.000689442860316129"
        iyz="-3.5958850430224E-07"
        izz="0.00056433773579828" />
    </inertial>
    <visual>
      <origin
        xyz="0 0 0"
        rpy="0 0 0" />
      <geometry>
        <mesh
          filename="package://dofnine4/meshes/Link4.STL" />
      </geometry>
      <material
        name="">
        <color
          rgba="1 1 1 1" />
      </material>
    </visual>
    <collision>
      <origin
        xyz="0 0 0"
        rpy="0 0 0" />
      <geometry>
        <mesh
          filename="package://dofnine4/meshes/Link4.STL" />
      </geometry>
    </collision>
  </link>
  <joint
    name="joint4"
    type="revolute">
    <origin
      xyz="-0.4 0 0.1"
      rpy="1.5708 0 0" />
    <parent
      link="Link3" />
    <child
      link="Link4" />
    <axis
      xyz="0 -1 0" />
    <limit
      lower="-3.14"
      upper="3.14"
      effort="100"
      velocity="3" />
  </joint>
  <link
    name="Link5">
    <inertial>
      <origin
        xyz="-1.10254394503073E-09 0.00606080729798903 -0.000876771161951687"
        rpy="0 0 0" />
      <mass
        value="0.539069799173127" />
      <inertia
        ixx="0.000700054524920547"
        ixy="2.80818700531353E-11"
        ixz="-3.75358864544162E-11"
        iyy="0.00062916185295728"
        iyz="-2.86426233934681E-06"
        izz="0.000545629458857338" />
    </inertial>
    <visual>
      <origin
        xyz="0 0 0"
        rpy="0 0 0" />
      <geometry>
        <mesh
          filename="package://dofnine4/meshes/Link5.STL" />
      </geometry>
      <material
        name="">
        <color
          rgba="1 1 1 1" />
      </material>
    </visual>
    <collision>
      <origin
        xyz="0 0 0"
        rpy="0 0 0" />
      <geometry>
        <mesh
          filename="package://dofnine4/meshes/Link5.STL" />
      </geometry>
    </collision>
  </link>
  <joint
    name="joint5"
    type="revolute">
    <origin
      xyz="0 0 0.1"
      rpy="-1.5708 0 0" />
    <parent
      link="Link4" />
    <child
      link="Link5" />
    <axis
      xyz="0 -1 0" />
    <limit
      lower="-3.14"
      upper="3.14"
      effort="100"
      velocity="3" />
  </joint>
  <link
    name="Link6">
    <inertial>
      <origin
        xyz="-3.33066907387547E-16 5.3776427755281E-17 -0.0250000000000002"
        rpy="0 0 0" />
      <mass
        value="0.00844911636473055" />
      <inertia
        ixx="2.33861406079627E-06"
        ixy="-1.2924697071142E-23"
        ixz="1.32000780054905E-21"
        iyy="2.33861406079627E-06"
        iyz="7.22353276953213E-23"
        izz="1.15676296962146E-06" />
    </inertial>
    <visual>
      <origin
        xyz="0 0 0"
        rpy="0 0 0" />
      <geometry>
        <mesh
          filename="package://dofnine4/meshes/Link6.STL" />
      </geometry>
      <material
        name="">
        <color
          rgba="1 1 1 1" />
      </material>
    </visual>
    <collision>
      <origin
        xyz="0 0 0"
        rpy="0 0 0" />
      <geometry>
        <mesh
          filename="package://dofnine4/meshes/Link6.STL" />
      </geometry>
    </collision>
  </link>
  <joint
    name="joint6"
    type="revolute">
    <origin
      xyz="0 0 0.1"
      rpy="0 0 0" />
    <parent
      link="Link5" />
    <child
      link="Link6" />
    <axis
      xyz="0 0 1" />
    <limit
      lower="-3.14"
      upper="3.14"
      effort="100"
      velocity="3" />
  </joint>
  <link
    name="Link7">
    <inertial>
      <origin
        xyz="3.18854742609176E-09 -0.297660360929499 2.98166331832994E-08"
        rpy="0 0 0" />
      <mass
        value="0.183617294024981" />
      <inertia
        ixx="0.00524294237262041"
        ixy="-1.42815452318038E-10"
        ixz="2.89096367391935E-13"
        iyy="9.23296314885479E-06"
        iyz="-1.3377812848702E-09"
        izz="0.00524285615727471" />
    </inertial>
    <visual>
      <origin
        xyz="0 0 0"
        rpy="0 0 0" />
      <geometry>
        <mesh
          filename="package://dofnine4/meshes/Link7.STL" />
      </geometry>
      <material
        name="">
        <color
          rgba="1 1 1 1" />
      </material>
    </visual>
    <collision>
      <origin
        xyz="0 0 0"
        rpy="0 0 0" />
      <geometry>
        <mesh
          filename="package://dofnine4/meshes/Link7.STL" />
      </geometry>
    </collision>
  </link>
  <joint
    name="joint7"
    type="prismatic">
    <origin
      xyz="0 0 0.04"
      rpy="1.5708 0 0" />
    <parent
      link="Link6" />
    <child
      link="Link7" />
    <axis
      xyz="0 1 0" />
    <limit
      lower="0.01"
      upper="0.5"
      effort="100"
      velocity="3" />
  </joint>
  <link
    name="Link8">
    <inertial>
      <origin
        xyz="0.0367515090957904 3.9743794338909E-08 4.67182923076515E-09"
        rpy="0 0 0" />
      <mass
        value="0.0238747438440848" />
      <inertia
        ixx="1.19707364590308E-06"
        ixy="-3.82912865565906E-11"
        ixz="-4.42953916227951E-12"
        iyy="1.44418724339531E-05"
        iyz="-8.14229112368807E-14"
        izz="1.45882633135747E-05" />
    </inertial>
    <visual>
      <origin
        xyz="0 0 0"
        rpy="0 0 0" />
      <geometry>
        <mesh
          filename="package://dofnine4/meshes/Link8.STL" />
      </geometry>
      <material
        name="">
        <color
          rgba="1 1 1 1" />
      </material>
    </visual>
    <collision>
      <origin
        xyz="0 0 0"
        rpy="0 0 0" />
      <geometry>
        <mesh
          filename="package://dofnine4/meshes/Link8.STL" />
      </geometry>
    </collision>
  </link>
  <joint
    name="joint8"
    type="revolute">
    <origin
      xyz="0 0 0"
      rpy="0 0 0" />
    <parent
      link="Link7" />
    <child
      link="Link8" />
    <axis
      xyz="0 0 -1" />
    <limit
      lower="-3.14"
      upper="3.14"
      effort="100"
      velocity="3" />
  </joint>
  <link
    name="Link9">
    <inertial>
      <origin
        xyz="0.0509634073607842 2.94902990916057E-17 -1.66533453693773E-16"
        rpy="0 0 0" />
      <mass
        value="0.0330778237140973" />
      <inertia
        ixx="1.63246639041242E-06"
        ixy="-5.33023335267237E-21"
        ixz="-1.56202327628569E-19"
        iyy="3.33087605310079E-05"
        iyz="-9.26063522676001E-22"
        izz="3.34236789352973E-05" />
    </inertial>
    <visual>
      <origin
        xyz="0 0 0"
        rpy="0 0 0" />
      <geometry>
        <mesh
          filename="package://dofnine4/meshes/Link9.STL" />
      </geometry>
      <material
        name="">
        <color
          rgba="1 1 1 1" />
      </material>
    </visual>
    <collision>
      <origin
        xyz="0 0 0"
        rpy="0 0 0" />
      <geometry>
        <mesh
          filename="package://dofnine4/meshes/Link9.STL" />
      </geometry>
    </collision>
  </link>
  <joint
    name="joint9"
    type="revolute">
    <origin
      xyz="0.08 0 0"
      rpy="-1.5708 0 0" />
    <parent
      link="Link8" />
    <child
      link="Link9" />
    <axis
      xyz="0 0 1" />
    <limit
      lower="-3.14"
      upper="3.14"
      effort="100"
      velocity="3" />
  </joint>
</robot>